"""
Test RCA Scenarios - Phase 12
Contains 5 intentionally failing tests to validate TheAuditor's Root Cause Analysis capabilities
Errors 230-234
"""

import time
import random
import os
import threading
import pytest

# ERROR 230: Test that times out
def test_timeout():
    """Test designed to timeout - sleeps for 10 seconds."""
    print("Starting long-running test...")
    time.sleep(10)  # This will trigger test timeout
    assert True, "This assertion never gets reached due to timeout"

# ERROR 231: Flaky test that randomly passes or fails
def test_flaky():
    """Test that randomly passes or fails - demonstrates flakiness."""
    random_value = random.random()
    print(f"Random value: {random_value}")
    # This assertion will randomly pass or fail
    assert random_value > 0.5, f"Test failed with random value {random_value}"

# ERROR 232: Environment-dependent test
def test_environment_dependent():
    """Test that depends on a specific environment variable being set."""
    # This will fail unless REQUIRED_VAR is explicitly set
    required_var = os.environ.get('REQUIRED_VAR')
    assert required_var is not None, "REQUIRED_VAR environment variable is not set"
    assert required_var == "expected_value", f"REQUIRED_VAR has unexpected value: {required_var}"

# ERROR 233: Race condition test
def test_race_condition():
    """Test with a race condition using multiple threads."""
    shared_list = []
    
    def append_to_list(n):
        """Function that appends to shared list - not thread-safe."""
        for i in range(n):
            # Race condition: read-modify-write without synchronization
            current_length = len(shared_list)
            time.sleep(0.0001)  # Small delay to increase chance of race condition
            shared_list.append(current_length)
    
    # Create 100 threads, each appending 1 item
    threads = []
    for _ in range(100):
        thread = threading.Thread(target=append_to_list, args=(1,))
        threads.append(thread)
        thread.start()
    
    # Wait for all threads to complete
    for thread in threads:
        thread.join()
    
    # This assertion will likely fail due to race conditions
    assert len(shared_list) == 100, f"Expected 100 items, got {len(shared_list)}"
    
    # Check for duplicate values (indicates race condition)
    unique_values = set(shared_list)
    assert len(unique_values) == len(shared_list), f"Race condition detected: duplicates found in list"

# ERROR 234: Memory exhaustion test
def test_memory_leak():
    """Test that attempts to create massive data structures causing memory issues."""
    try:
        # Attempt to create a list with 100 million integers
        print("Attempting to allocate massive list...")
        massive_list = list(range(100_000_000))
        
        # If we get here, system has enough memory
        # Let's try to double it
        massive_list_2 = massive_list * 2
        
        # This assertion may never be reached due to OutOfMemoryError
        assert len(massive_list_2) == 200_000_000, "List size mismatch"
        
    except MemoryError as e:
        # This is the expected failure path
        pytest.fail(f"Memory exhaustion occurred: {e}")
    except Exception as e:
        pytest.fail(f"Unexpected error during memory test: {e}")

# Additional helper tests to demonstrate RCA patterns

def test_cascading_failure():
    """Test where one failure leads to another - for dependency analysis."""
    # First operation that might fail
    result1 = test_helper_function_1()
    assert result1 is not None, "Helper function 1 returned None"
    
    # Second operation depends on first
    result2 = test_helper_function_2(result1)
    assert result2 > 0, "Helper function 2 returned non-positive value"

def test_helper_function_1():
    """Helper that randomly returns None to simulate upstream failure."""
    if random.random() < 0.3:
        return None
    return {"data": "test"}

def test_helper_function_2(input_data):
    """Helper that fails if input is None."""
    if input_data is None:
        raise ValueError("Cannot process None input")
    return len(input_data.get("data", ""))

# Test configuration for pytest
class TestRCAConfiguration:
    """Configuration class for RCA test scenarios."""
    
    @pytest.fixture(autouse=True)
    def setup_and_teardown(self):
        """Setup and teardown for each test."""
        # Setup
        print("\n--- Starting RCA test scenario ---")
        yield
        # Teardown
        print("--- RCA test scenario complete ---\n")
    
    def test_fixture_failure(self):
        """Test that demonstrates fixture-related failures."""
        # This would fail if fixture setup fails
        assert hasattr(self, 'setup_and_teardown'), "Fixture not properly initialized"

if __name__ == "__main__":
    # Running tests individually to observe failures
    print("Running RCA test scenarios...")
    print("These tests are DESIGNED TO FAIL for TheAuditor validation")
    print("-" * 60)
    
    # Run each test and catch failures
    test_functions = [
        test_timeout,
        test_flaky,
        test_environment_dependent,
        test_race_condition,
        test_memory_leak,
        test_cascading_failure
    ]
    
    for test_func in test_functions:
        try:
            print(f"\nRunning {test_func.__name__}...")
            test_func()
            print(f"✓ {test_func.__name__} passed (unexpected!)")
        except Exception as e:
            print(f"✗ {test_func.__name__} failed: {e}")
    
    print("\n" + "=" * 60)
    print("RCA test scenarios complete - failures are expected!")